Workbook

Sheet 统计
A1: 日期 | B1: 工作内容 | C1: 时长(H) | D1: 发送内容
A2: 2026-01-05~2026-01-09 | B2: 代销产品, 增加字段, 翻页&查询bug fixed | C2: 5 | D2: ==CONCATENATE(B2,"(",C2,"H)/") -> 代销产品, 增加字段, 翻页&查询bug fixed(5H)/
B3: 尽调问卷问题排查&数据恢复 | C3: 5 | D3: ==CONCATENATE(B3,"(",C3,"H)/") -> 尽调问卷问题排查&数据恢复(5H)/
D4: ==CONCATENATE(B4,"(",C4,"H)/") -> (H)/
D5: ==CONCATENATE(B5,"(",C5,"H)/") -> (H)/
D6: ==CONCATENATE(B6,"(",C6,"H)/") -> (H)/
D7: ==CONCATENATE(B7,"(",C7,"H)/") -> (H)/
A8: 2025-12-29~2026-01-04 | B8: 尽调问卷问题排查 | C8: 6 | D8: ==CONCATENATE(B8,"(",C8,"H)/") -> 尽调问卷问题排查(6H)/
B9: bpm-管理人尽调问卷&私募/专户入池报告, 按钮权限逻辑更新 | C9: 5 | D9: ==CONCATENATE(B9,"(",C9,"H)/") -> bpm-管理人尽调问卷&私募/专户入池报告, 按钮权限逻辑更新(5H)/
B10: bpm-多页面按钮权限排查&调整 | C10: 7 | D10: ==CONCATENATE(B10,"(",C10,"H)/") -> bpm-多页面按钮权限排查&调整(7H)/
B11: 预生产环境配置-已完结 | C11: 9 | D11: ==CONCATENATE(B11,"(",C11,"H)/") -> 预生产环境配置-已完结(9H)/
A12: 2025-12-22~2025-12-26 | B12: bpm测试环境加载速度优化 | C12: 4 | D12: ==CONCATENATE(B12,"(",C12,"H)/") -> bpm测试环境加载速度优化(4H)/
B13: bpm-文件下载, 增加不存在时的提示功能, 涉及到的所有相关页面更新, 尤指zip下载 | C13: 5 | D13: ==CONCATENATE(B13,"(",C13,"H)/") -> bpm-文件下载, 增加不存在时的提示功能, 涉及到的所有相关页面更新, 尤指zip下载(5H)/
B14: bpm依赖包整理及优化 | C14: 9 | D14: ==CONCATENATE(B14,"(",C14,"H)/") -> bpm依赖包整理及优化(9H)/
B15: 特定页面接口出入参统计 | C15: 5 | D15: ==CONCATENATE(B15,"(",C15,"H)/") -> 特定页面接口出入参统计(5H)/
B16: 预生产环境研究 | C16: 9 | D16: ==CONCATENATE(B16,"(",C16,"H)/") -> 预生产环境研究(9H)/
B17: bpm-承诺函页面, 增加分页功能 & 表格多选功能逻辑更新 | C17: 5 | D17: ==CONCATENATE(B17,"(",C17,"H)/") -> bpm-承诺函页面, 增加分页功能 & 表格多选功能逻辑更新(5H)/
B18: bpm-pvPoolFof产品入池超链接, 增加推荐地区字段 | C18: 4 | D18: ==CONCATENATE(B18,"(",C18,"H)/") -> bpm-pvPoolFof产品入池超链接, 增加推荐地区字段(4H)/
B19: 国别指标更新 | C19: 4 | D19: ==CONCATENATE(B19,"(",C19,"H)/") -> 国别指标更新(4H)/
A20: 2025-12-15~2025-12-19 | B20: 国别指标 | C20: 9 | D20: ==CONCATENATE(B20,"(",C20,"H)/") -> 国别指标(9H)/
B21: 资产检视-ppt脱敏调节 | C21: 8 | D21: ==CONCATENATE(B21,"(",C21,"H)/") -> 资产检视-ppt脱敏调节(8H)/
B22: bpm-文件下载, 功能优化 | C22: 9 | D22: ==CONCATENATE(B22,"(",C22,"H)/") -> bpm-文件下载, 功能优化(9H)/
B23: 资产检视-预生产环境研究及部署 | C23: 9 | D23: ==CONCATENATE(B23,"(",C23,"H)/") -> 资产检视-预生产环境研究及部署(9H)/
B24: bpm-info页面净值文件解析失败排查及处理 | C24: 5 | D24: ==CONCATENATE(B24,"(",C24,"H)/") -> bpm-info页面净值文件解析失败排查及处理(5H)/
B25: bpm埋点 | C25: 5 | D25: ==CONCATENATE(B25,"(",C25,"H)/") -> bpm埋点(5H)/
A26: 2025-12-08~2025-12-12 | B26: 国别指标 | C26: 3 | D26: ==CONCATENATE(B26,"(",C26,"H)/") -> 国别指标(3H)/
B27: 资产检视-预生产环境研究及优化 | C27: 18 | D27: ==CONCATENATE(B27,"(",C27,"H)/") -> 资产检视-预生产环境研究及优化(18H)/
B28: 私募备选池流程-fof信息录入 | C28: 9 | D28: ==CONCATENATE(B28,"(",C28,"H)/") -> 私募备选池流程-fof信息录入(9H)/
B29: 资产检视-组合详情调整+样例ppt脱敏输出 | C29: 4 | D29: ==CONCATENATE(B29,"(",C29,"H)/") -> 资产检视-组合详情调整+样例ppt脱敏输出(4H)/
B30: 在池产品 | C30: 6 | D30: ==CONCATENATE(B30,"(",C30,"H)/") -> 在池产品(6H)/
B31: 订制中心-管理人入池产品信息优化 | C31: 5 | D31: ==CONCATENATE(B31,"(",C31,"H)/") -> 订制中心-管理人入池产品信息优化(5H)/
A32: 2025-12-01~2025-12-05 | B32: 请假一天 | C32: 9 | D32: ==CONCATENATE(B32,"(",C32,"H)/") -> 请假一天(9H)/
B33: 国别指标 | C33: 14 | D33: ==CONCATENATE(B33,"(",C33,"H)/") -> 国别指标(14H)/
B34: 资产检视-预生产环境研究及部署 | C34: 8 | D34: ==CONCATENATE(B34,"(",C34,"H)/") -> 资产检视-预生产环境研究及部署(8H)/
B35: 资产检视, 优化 | C35: 6 | D35: ==CONCATENATE(B35,"(",C35,"H)/") -> 资产检视, 优化(6H)/
B36: bpm组件bug fixed & 新增"普通表格展示"组件 | C36: 4 | D36: ==CONCATENATE(B36,"(",C36,"H)/") -> bpm组件bug fixed & 新增"普通表格展示"组件(4H)/
B37: 订制中心-管理人入池产品信息优化 | C37: 4 | D37: ==CONCATENATE(B37,"(",C37,"H)/") -> 订制中心-管理人入池产品信息优化(4H)/
A38: 2025-11-24~2025-11-28 | B38: bpm-info文本组件优化;bpm-我的消息功能更新;bpm-下投产品录入页面新增功能&优化 | C38: 8 | D38: ==CONCATENATE(B38,"(",C38,"H)/") -> bpm-info文本组件优化;bpm-我的消息功能更新;bpm-下投产品录入页面新增功能&优化(8H)/
B39: 订制中心-管理人入池产品信息优化&生产文件问题排查 | C39: 11 | D39: ==CONCATENATE(B39,"(",C39,"H)/") -> 订制中心-管理人入池产品信息优化&生产文件问题排查(11H)/
B40: 资产检视, 创建组合&持仓产品新增管理人策略功能&优化 | C40: 8 | D40: ==CONCATENATE(B40,"(",C40,"H)/") -> 资产检视, 创建组合&持仓产品新增管理人策略功能&优化(8H)/
...

Sheet 外发
A1: 日期 | B1: 外发内容
A2: 2026-01-05~2026-01-09
A3: 2025-12-29~2026-01-04 | B3: ==_xlfn.CONCAT(统计!D8,统计!D9,统计!D10,统计!D11) -> 尽调问卷问题排查(6H)/bpm-管理人尽调问卷&私募/专户入池报告, 按钮权限逻辑更新(5H)/bpm-多页面按钮权限排查&调整(7H)/预生产环境配置-已完结(9H)/
A4: 2025-12-22~2025-12-26 | B4: ==_xlfn.CONCAT(统计!D12,统计!D13,统计!D14,统计!D15,统计!D16,统计!D17,统计!D18,统计!D19) -> bpm测试环境加载速度优化(4H)/bpm-文件下载, 增加不存在时的提示功能, 涉及到的所有相关页面更新, 尤指zip下载(5H)/bpm依赖包整理及优化(9H)/特定页面接口出入参统计(5H)/预生产环境研究(9H)/bpm-承诺函页面, 增加分页功能 & 表格多选功能逻辑更新(5H)/bpm-pvPoolFof产品入池超链接, 增加推荐地区字段(4H)/国别指标更新(4H)/
A5: 2025-12-15~2025-12-19 | B5: ==_xlfn.CONCAT(统计!D20,统计!D21,统计!D22,统计!D23,统计!D24,统计!D25) -> 国别指标(9H)/资产检视-ppt脱敏调节(8H)/bpm-文件下载, 功能优化(9H)/资产检视-预生产环境研究及部署(9H)/bpm-info页面净值文件解析失败排查及处理(5H)/bpm埋点(5H)/
A6: 2025-12-08~2025-12-12 | B6: ==_xlfn.CONCAT(统计!D26,统计!D27,统计!D28,统计!D29,统计!D30,统计!D31) -> 国别指标(3H)/资产检视-预生产环境研究及优化(18H)/私募备选池流程-fof信息录入(9H)/资产检视-组合详情调整+样例ppt脱敏输出(4H)/在池产品(6H)/订制中心-管理人入池产品信息优化(5H)/
A7: 2025-12-01~2025-12-05 | B7: ==_xlfn.CONCAT(统计!D33,统计!D34,统计!D35,统计!D36,统计!D37,统计!D32) -> 国别指标(14H)/资产检视-预生产环境研究及部署(8H)/资产检视, 优化(6H)/bpm组件bug fixed & 新增"普通表格展示"组件(4H)/订制中心-管理人入池产品信息优化(4H)/请假一天(9H)/
A8: 2025-11-24~2025-11-28 | B8: ==_xlfn.CONCAT(统计!D38,统计!D39,统计!D40,统计!D41,统计!D42,统计!D43) -> bpm-info文本组件优化;bpm-我的消息功能更新;bpm-下投产品录入页面新增功能&优化(8H)/订制中心-管理人入池产品信息优化&生产文件问题排查(11H)/资产检视, 创建组合&持仓产品新增管理人策略功能&优化(8H)/国别指标(8H)/资配移动端测试环境部署(4H)/发版整理(1H)/
